Workbook
Name FINISHES_NET_TOTAL: 'Finishes Cover'!$F$30
Name FINISHES_GRAND_TOTAL: 'Finishes Cover'!$F$36
Name ICF_PACKAGE_TOTAL: 'Finishes Cover'!$F$39
Name COMBINED_TOTAL: 'Finishes Cover'!$F$40

Sheet Cover
A10: BILL OF QUANTITIES
A11: ICF KIT · CONCRETE · LABOUR
A14: PLOT 1 RIVENDELL PARK, DOUGLAS
A15: Single Dwelling with Basement + ICF Pool Tank · Douglas, Lanark, South Lanarkshire ML11 8EB · SCOTLAND
B17: Quotation Reference | C17: ES26-084
B18: Project | C18: Plot 1 Rivendell Park, Douglas
B19: House Type | C19: Single dwelling: 10in Std basement + pool tank, 6in XR35 GF (cores aligned), RC slabs, vaulted cut roof
B20: Client | C20: Mr K & Mrs Burrell
B21: Site Address | C21: New Dwelling at Plot 1 Rivendell Park, Douglas, Lanark, South Lanarkshire ML11 8EB
B22: BOQ Issued | C22: 20 October 2026
B23: BOQ Reference | C23: BOQ-ES26-084-001 · Revision 1.0
B24: Prepared by | C24: Tom Smith — BuildEase Manager, Nudura UK
B25: Issued by | C25: Tremco Construction Products Group
B26: Currency | C26: Pound Sterling (GBP) · VAT at 20%
B27: Measurement Convention | C27: RICS New Rules of Measurement (NRM2)
B29: IMPORTANT NOTICE — DISCLAIMER
B30: • This Bill of Quantities is supplied in good faith based on the BuildEase take-off models for Plot 1 Rivendell Park, Douglas and the associated Tremco CPG quotation.
B31: • ALL QUANTITIES SHOULD BE INDEPENDENTLY CHECKED AND VERIFIED BY THE PROJECT QS / QUANTITY SURVEYOR before tender submission, ordering or contract award.
B32: • This BOQ does NOT include an external render / finish allowance. Any render, coatings or external wall finish must be measured and priced separately.
B33: • Section C (Concrete) volumes are geometric voids — allow ~3% web displacement deduction and ~5% wastage on top when ordering ready-mix.
B34: • Section D (Labour) day estimates are scaled proportionately from a reference project; actual gang productivity will vary with site conditions, weather and trade experience.
B35: • BuildEase, Tremco Construction Products Group and Nudura UK accept no liability for tender or contract outcomes arising from the use of these figures. If in doubt — ask.
B36: • Contact: Tom Smith — BuildEase Manager, Nudura UK — for clarification on any quantity or rate basis in this document.
A38: SCOTLAND: the design must satisfy the Building Standards (Scotland) technical handbooks (building warrant from South Lanarkshire Council) - not the English Approved Documents / LABC. Building height ~6.3 m above the ground floor (ridge) - below 11 m.
A39: NOT FOR CONSTRUCTION. The two "floor" slots of the programme and D.2 are RC slabs by others (basement raft, GF suspended slab); slab concrete, rebar and pumping are NOT in this ICF BOQ (coordination quantities in the finishes package Bill 6). Engineer to design: the GF slab over the pool and the garage, the 4.55 m garage door lintel, the vaulted roof ridge beams / posts and the glazed gables.

Sheet Contents
A1: CONTENTS
A4: Section | B4: Description | C4: Sheet | D4: Status
B5: Cover & Project Information | C5: Cover
B6: Contents | C6: Contents
B7: Indicative Programme (Gantt) | C7: Programme | D7: Information
B8: Summary of Tender Pricing | C8: Summary
A9: A | B9: Preliminaries | C9: A_Preliminaries | D9: Contractor priced
A10: B | B10: ICF Kit Supply | C10: B_ICF_Supply | D10: Pre-priced
A11: C | B11: Concrete Supply, Pump & Placement | C11: C_Concrete | D11: Contractor priced
A12: D | B12: Labour — ICF, Floors & Roofs | C12: D_Labour | D12: Contractor priced
A13: F | B13: Reference Data (informative only) | C13: F_Reference | D13: —

Sheet Programme
A1: PROG · INDICATIVE INSTALL PROGRAMME — RESOURCE-LEVELLED, ONE COLUMN PER WORKING DAY
A2: Group-by-group sequential build with a staggered start between groups. ICF install + snag + pour cycles, intermediate floors and roof structure are completed before moving on. Resourcing and durations below are indicative and must be validated by site management. Render / external finish is NOT included in this programme.
F3: W1 | M3: W2 | T3: W3 | AA3: W4 | AH3: W5
A4: Group | B4: Plots | C4: Forms | D4: Weeks | E4: Start wk | F4: M | G4: T | H4: W | I4: T | J4: F | K4: S | L4: S | M4: M | N4: T | O4: W | P4: T | Q4: F | R4: S | S4: S | T4: M | U4: T | V4: W | W4: T | X4: F | Y4: S | Z4: S | AA4: M | AB4: T | AC4: W | AD4: T | AE4: F | AF4: S | AG4: S | AH4: M | AI4: T | AJ4: W | AK4: T | AL4: F | AM4: S | AN4: S
A5: Plot 1 dwelling | B5: 1 | C5: 449 | D5: 5 | E5: 1
A7: LEGEND
C8: ICF walls — first lift: pool tank P (erection, snag & pour)
C9: ICF walls — basement BL (on the raft), master-suite footing FB and GF L1 (after the GF slab)
C10: Concrete pour — sized at 60 m3 per pump-day (1 day per lift here), ICF crew attends, pump on site
C11: Curing — pours held to Fridays where possible so the 2 curing days fall on the weekend; a mid-week pour cures 2 working days
C12: RC slab by others — basement raft after the pool tank; GF suspended slab after the basement (1 day each by Tom's rule)
C13: Vaulted roof structure (cut rafters on ridge beams), 1 day by Tom's rule
A15: RESOURCING
A16: • 1 ICF crews of 8 trained installers (each crew = 2 four-man gang-equivalents) erect the wall lifts, moving to the next ready block while a floor is fitted; 1 joinery crew of 3 fits every intermediate floor and roof (Tom's rule 19.10.26: floors 1 day per plot, roofs 1 day per plot - one plot; the two 'floors' here are RC slabs by others (basement raft, GF suspended slab), the roof is the vaulted cut roof). Programme is resource-levelled day by day (white = block waiting for a crew).
A17: • Total ICF site programme: 5 working weeks (ICF erection, floors and roofs). Section A Preliminaries are quantified against this 5-week programme.
A18: • EXTERNAL RENDER / FINISH IS EXCLUDED from this BOQ and this programme. Where a render system is later specified, allow a separate workstream — per BBA guidance, render cannot begin until the concrete core has cured for a minimum of 28 days after the final pour.
A19: • Concrete pump booked on the pour days for each group (see Section C).
A20: • Lead time for BuildEase Pre-Cut Service: 5–6 weeks from order placement; procurement runs in parallel with mobilisation.
A21: • Programme estimates are provided in good faith and must be verified by the project / site management team.
A22: • SCOTLAND: the design must satisfy the Building Standards (Scotland) technical handbooks (building warrant from South Lanarkshire Council) - not the English Approved Documents / LABC. Building height ~6.3 m above the ground floor (ridge) - below 11 m.
A23: • Tom's rule (19.10.26): floors 1 day PER PLOT, roofs 1 day PER PLOT - one plot here, so each RC slab slot and the vaulted roof are shown at 1 day. The floor rows of this programme are RC SLABS BY OTHERS (basement raft after the pool tank - groundworks / engineer; GF suspended slab after the basement - engineer / frame contractor), NOT timber joists; slab concrete, rebar, falsework and slab pumping are NOT in this ICF BOQ (coordination quantities in the finishes package Bill 6).
A24: • Build sequence (no client programme issued): pool tank P (3 courses, on the pool base slab) -> pour -> basement raft -> basement BL (8 courses) -> pour -> GF suspended slab -> master-suite footing FB (2 courses) -> pour -> GF L1 (14 courses incl. the raked gables) -> pour -> vaulted roof. The FB pour (~2.5 m3) could share the GF slab pump visit or the L1 pour to save a pump day - not assumed.
A25: • ICF pours sized at 60 m3 per pump per day from each lift's own concrete volume (all four ICF pours are 1 pump day each here).
A26: • PROGRAMME (BOQ Builder sheet 'Programme', 1 ICF crew of 8 + 1 joinery crew of 3, Tom's rule floors / roofs 1 day per plot, pours at 60 m3 / pump-day): 21 working days = 5 weeks. Sequence: ICF P d0-0.46; pour d1-2; cure d2-4; basement raft 300 RC d4-5; ICF BL d5-6.98; pour d9-10; GF suspended RC slab 250 d10-11; ICF FB d11-11.15; pour d14-15; ICF L1 d15-16.68; pour d19-20; vaulted roof structure d20-21. ICF concrete 98.32 m3 (geometric, ordered forms) in 4 pump days. ALIGNMENT: the proposal Rev B prices 3 stillages x 6 weeks hire (GBP 1,440.00); on this programme the alignment is needed from the first ICF lift (pool tank, day 0) to the last pour (GF L1, day 20) = 4 weeks on hire - 2 weeks LESS than priced (GBP 480.00 of hire not needed on this programme). SENSITIVITY: Tom's 1-day floor rule is written for timber floors; the two slabs here are RC (basement raft, GF suspended slab over the pool and the garage) - with 10 working days per slab for falsework / rebar / pour / cure before loading (engineer to confirm) the programme is 8 weeks and the alignment is on hire 8 weeks (+2 vs the 6 priced) unless it is off-hired between lifts. The proposal has NOT been changed - confirm the hire period with the client / site team.
A27: • Basement + pool tank concrete: mix / waterproofing admixture and waterstops to the BS 8102 waterproofing designer and the engineer.

Sheet Summary
A1: SUMMARY OF TENDER PRICING
A3: Section totals are carried forward from each Bill section. Pre-priced columns show values from the associated Tremco CPG quotation; contractor-priced columns populate automatically when rates are entered in the section sheets. This BOQ excludes external render.
A5: Section | B5: Description | C5: Pre-priced (£) | D5: Contractor-priced (£) | E5: Section Total (£)
A6: A | B6: Preliminaries | D6: ='A_Preliminaries'!F1000 | E6: =IF(ISNUMBER(C6),C6,0)+IF(ISNUMBER(D6),D6,0)
A7: B | B7: ICF Kit Supply | C7: 29139.75 | E7: =IF(ISNUMBER(C7),C7,0)+IF(ISNUMBER(D7),D7,0)
A8: C | B8: Concrete Supply, Pump & Placement | D8: ='C_Concrete'!F1000 | E8: =IF(ISNUMBER(C8),C8,0)+IF(ISNUMBER(D8),D8,0)
A9: D | B9: Labour — ICF, Floors & Roofs | D9: ='D_Labour'!F1000 | E9: =IF(ISNUMBER(C9),C9,0)+IF(ISNUMBER(D9),D9,0)
B11: NET TOTAL (excluding VAT) | C11: =SUM(C6:C9) | D11: =SUM(D6:D9) | E11: =SUM(E6:E9)
B12: VAT @ 20% | E12: =E11*0.20
B13: GRAND TOTAL (inclusive of VAT) | E13: =E11+E12
A17: SIGNATURES
A19: Priced by
A20: Tendered by
A21: Approved by

Sheet A_Preliminaries
A1: A · PRELIMINARIES
A2: Items priced per working week against the site programme total of 5 weeks (see Programme sheet). Quantities are pre-populated; the contractor inserts the weekly rate.
A4: Ref | B4: Description | C4: Unit | D4: Qty | E4: Rate (£) | F4: Total (£)
A5: A.1 | B5: Site set-up, fencing, signage, induction & welfare establishment | C5: item | D5: 1 | F5: =IF(AND(ISNUMBER(D5),ISNUMBER(E5)),D5*E5,0)
A6: A.2 | B6: Welfare facilities — canteen, drying, toilets (hire) | C6: wk | D6: 5 | F6: =IF(AND(ISNUMBER(D6),ISNUMBER(E6)),D6*E6,0)
A7: A.3 | B7: Contract management & site supervision | C7: wk | D7: 5 | F7: =IF(AND(ISNUMBER(D7),ISNUMBER(E7)),D7*E7,0)
A8: A.4 | B8: Health & Safety, RAMS, CDM consultancy | C8: wk | D8: 5 | F8: =IF(AND(ISNUMBER(D8),ISNUMBER(E8)),D8*E8,0)
A9: A.5 | B9: Public liability and contract works insurance | C9: item | D9: 1 | F9: =IF(AND(ISNUMBER(D9),ISNUMBER(E9)),D9*E9,0)
A10: A.6 | B10: Scaffolding — independent access for ICF erection | C10: wk | D10: 5 | F10: =IF(AND(ISNUMBER(D10),ISNUMBER(E10)),D10*E10,0)
A11: A.7 | B11: Plant hire — telehandler / forklift for offload & ICF moves | C11: wk | D11: 5 | F11: =IF(AND(ISNUMBER(D11),ISNUMBER(E11)),D11*E11,0)
A12: A.8 | B12: Plant hire — small tools, generators, power & lighting | C12: wk | D12: 5 | F12: =IF(AND(ISNUMBER(D12),ISNUMBER(E12)),D12*E12,0)
A13: A.9 | B13: Hoarding / site enclosure / security | C13: wk | D13: 5 | F13: =IF(AND(ISNUMBER(D13),ISNUMBER(E13)),D13*E13,0)
A14: A.10 | B14: Temporary services — water, power, lighting (hire) | C14: wk | D14: 5 | F14: =IF(AND(ISNUMBER(D14),ISNUMBER(E14)),D14*E14,0)
A15: A.11 | B15: Site clean, waste management & skip rotation | C15: wk | D15: 5 | F15: =IF(AND(ISNUMBER(D15),ISNUMBER(E15)),D15*E15,0)
A16: A.12 | B16: Setting out and surveying — engineer's level checks | C16: wk | D16: 5 | F16: =IF(AND(ISNUMBER(D16),ISNUMBER(E16)),D16*E16,0)
A17: A.13 | B17: Site take-down, hand-over & demobilisation | C17: item | D17: 1 | F17: =IF(AND(ISNUMBER(D17),ISNUMBER(E17)),D17*E17,0)
A18: A.14 | B18: Pre-completion sound test (Approved Document E) | C18: test | F18: =IF(AND(ISNUMBER(D18),ISNUMBER(E18)),D18*E18,0)
A19: A.15 | B19: Air-tightness test (Approved Document L) | C19: test | F19: =IF(AND(ISNUMBER(D19),ISNUMBER(E19)),D19*E19,0)
A20: A.16 | B20: Day works allowance | C20: sum | F20: =IF(AND(ISNUMBER(D20),ISNUMBER(E20)),D20*E20,0)
B22: A — PRELIMINARIES SUBTOTAL | F22: =SUM(F5:F20)
F1000: =F22

Sheet B_ICF_Supply
A1: B · ICF KIT SUPPLY
A2: ICF material supply values are pre-priced from the associated Tremco CPG quotation. Pre-cut service fees are taken from each BuildEase take-off.
A4: Ref | B4: Description | C4: Unit | D4: Qty | E4: Rate (£) | F4: Total (£)
A5: B.1 — ICF Block, Forms & Accessories
A6: B.1 | B6: ICF Materials — Plot 1 dwelling (1 plot(s), 449 forms) | C6: group | D6: 1 | E6: 24872.37 | F6: =IF(AND(ISNUMBER(D6),ISNUMBER(E6)),D6*E6,0)
A8: B.2 — BuildEase Pre-Cut Service Fee
A9: B.2 | B9: Pre-Cut Service — Plot 1 dwelling | C9: group | D9: 1 | E9: 1702.62 | F9: =IF(AND(ISNUMBER(D9),ISNUMBER(E9)),D9*E9,0)
A11: B.3 — Haulage
A12: B.3 | B12: Haulage to site — 2 loads: 2 x artic @ 170.8 mi (proposal Rev B delivery schedule: substructure, then GF) | C12: item | D12: 1 | E12: 1124.76 | F12: =IF(AND(ISNUMBER(D12),ISNUMBER(E12)),D12*E12,0)
A14: B.4 — Alignment System
A15: B.4 | B15: Alignment System Rental — Plot 1 dwelling (42 systems) | C15: group | D15: 1 | E15: 1440 | F15: =IF(AND(ISNUMBER(D15),ISNUMBER(E15)),D15*E15,0)
B17: B — ICF KIT SUPPLY SUBTOTAL | F17: =SUM(F5:F15)
F1000: =F17

Sheet C_Concrete
A1: C · CONCRETE SUPPLY, PUMP & PLACEMENT
A2: Volumes are geometric void calculations (block length × course height × core thickness). Allow ~3% for plastic web displacement and ~5% wastage when ordering. Rates to be inserted by the contractor.
A4: Ref | B4: Description | C4: Unit | D4: Qty | E4: Rate (£) | F4: Total (£)
A5: C.1 — Ready-Mix Concrete Supply (C28/35 typical to BS 8500; basement + pool tank mix / admixture to the BS 8102 designer)
A6: C.1 | B6: Ready-mix concrete — Plot 1 dwelling (1 plot(s), geometric void) | C6: m³ | D6: 98.32 | F6: =IF(AND(ISNUMBER(D6),ISNUMBER(E6)),D6*E6,0)
A8: C.2 — Concrete Pump Hire
A9: C.2 | B9: Boom pump hire — Plot 1 dwelling | C9: day | D9: 4 | F9: =IF(AND(ISNUMBER(D9),ISNUMBER(E9)),D9*E9,0)
A10: C.2 | B10: Pump mobilisation / demobilisation | C10: item | D10: 1 | F10: =IF(AND(ISNUMBER(D10),ISNUMBER(E10)),D10*E10,0)
A12: C.3 — Concrete Vibration & Placement Plant
A13: C.3 | B13: Internal poker vibrator hire — site duration | C13: wk | D13: 5 | F13: =IF(AND(ISNUMBER(D13),ISNUMBER(E13)),D13*E13,0)
A14: C.3 | B14: Concrete banksman / poker operator | C14: day | F14: =IF(AND(ISNUMBER(D14),ISNUMBER(E14)),D14*E14,0)
B16: C — CONCRETE SUBTOTAL | F16: =SUM(F5:F14)
F1000: =F16

Sheet D_Labour
A1: D · LABOUR — ICF INSTALL, FLOORS & ROOFS
A2: ICF install days scaled proportionately against the Maycroft reference (52.65 forms per gang-day). Rates below are per 4-man gang per day. Floor and roof allowances are taken per group from the project configuration.
A4: Ref | B4: Description | C4: Unit | D4: Qty | E4: Rate (£) | F4: Total (£)
A5: D.1 — ICF Install Gang
A6: D.1 | B6: ICF install — Plot 1 dwelling (449 forms ÷ 52.65 forms/day = 8.5 gang-days) | C6: gang-day | D6: 8.5 | F6: =IF(AND(ISNUMBER(D6),ISNUMBER(E6)),D6*E6,0)
A7: D.1 | B7: Snag, pour & cure attendance (30% allowance, project total) | C7: gang-day | D7: 2.6 | F7: =IF(AND(ISNUMBER(D7),ISNUMBER(E7)),D7*E7,0)
A9: D.2 — RC Slabs by Others (basement raft — groundworks; GF suspended slab — engineer / frame contractor): programme days, NOT ICF labour
A10: D.2 | B10: RC slabs by others (raft + GF slab; programme days) — Plot 1 dwelling (2 floors × 1 gang-days) | C10: gang-day | D10: 2 | F10: =IF(AND(ISNUMBER(D10),ISNUMBER(E10)),D10*E10,0)
A12: D.3 — Roof Structure Labour (vaulted cut roof: 63 x 220 C24 rafters @ 600 on ridge beams + 3 SHS posts)
A13: D.3 | B13: Roof structure — Plot 1 dwelling | C13: gang-day | D13: 1 | F13: =IF(AND(ISNUMBER(D13),ISNUMBER(E13)),D13*E13,0)
B15: D — LABOUR SUBTOTAL | F15: =SUM(F5:F13)
F1000: =F15

Sheet F_Reference
A1: F · REFERENCE DATA (informative only)
A2: Per-group quantities calculated from the BuildEase take-off models. Values feed into Sections C and D. Render is excluded from this BOQ.
A4: Group | B4: Plots | C4: Forms | D4: Concrete (m³) | E4: ICF install days | F4: Floor + Roof days | G4: Pre-cut (£)
A5: Plot 1 dwelling | B5: 1 | C5: 449 | D5: 98.32 | E5: 8.5 | F5: 3 | G5: 1702.62
A6: SITE | B6: 1 | C6: 449 | D6: 98.32 | E6: 8.5 | F6: 3 | G6: 1702.62
A9: PER-LIFT FORM BREAKDOWN
A10: Group | B10: Lift | C10: 4" Std | D10: 6" XR35 str | E10: 6" XR35 cnr | F10: 10" Std | G10: Lift total
A11: Plot 1 dwelling | B11: P | C11: 0 | D11: 0 | E11: 0 | F11: 48 | G11: 48
A12: Plot 1 dwelling | B12: BL | C12: 0 | D12: 0 | E12: 0 | F12: 208 | G12: 208
A13: Plot 1 dwelling | B13: FB | C13: 0 | D13: 12 | E13: 4 | F13: 0 | G13: 16
A14: Plot 1 dwelling | B14: L1 | C14: 0 | D14: 140 | E14: 37 | F14: 0 | G14: 177
A17: GEOMETRIC CONSTANTS & CALCULATION BASIS
A18: Block length | C18: 2.438 m | E18: 96 inches
A19: Course height | C19: 0.4574 m | E19: 18 inches
A20: 4" Std straight volume | C20: 0.1133 m³ | E20: =length × course × core
A21: 6" XR35 straight volume | C21: 0.1699 m³ | E21: =length × course × core
A22: 10" Std straight volume | C22: 0.2832 m³ | E22: =length × course × core
A23: 4" Std corner volume | C23: 0.0511 m³ | E23: L-void; long 31.625" / short 15.625"
A24: 6" XR35 corner volume | C24: 0.1133 m³ | E24: L-void; long 43" / short 27"
A25: Maycroft install rate | C25: 52.65 forms/day | E25: Reference: 1053 forms ÷ 20 days

Sheet Finishes Cover
C1: Bill of Quantities Package - Finishes & Ancillary Trades
C2: ES26-084 | Plot 1 Rivendell Park, Douglas | Mr K & Mrs Burrell
A4: DISCLAIMER: This information is supplied in good faith for guidance and coordination only. It is not part of the Nudura ICF price and must be checked and verified by the appropriate professional (quantity surveyor, designer, engineer or supplier) before use. Only the Nudura ICF formwork and associated accessories are included in our price. Quantities are measured from the BuildEase quotation model of the Foote McBride planning drawings (C2523 PP 01 001-008, raster, no sections / dimensions / levels - heights scaled from the elevations); no allowance for waste is included unless stated. Quantity columns are the model levels P / BL / FB / L1; the Site total is their sum. Rates and amounts are by others.
A6: Project | B6: Plot 1 Rivendell Park, Douglas
A7: Site | B7: New Dwelling at Plot 1 Rivendell Park, Douglas, Lanark, South Lanarkshire ML11 8EB
A8: Client | B8: Mr K & Mrs Burrell
A9: Architect | B9: Foote McBride Associates (C2523 PP 01 001-008, Jan 26, Council Approval - planning only)
A10: Quotation ref | B10: ES26-084
A11: Document | B11: Bill of Quantities Package - Finishes & Ancillary Trades
A12: Issue | B12: 01 (20/10/2026)
A13: Scope | B13: One dwelling: ICF pool tank (10in Std) + basement (10in Std, garage, laundry, stores, pool hall) + master-suite footing and GF (6in XR35, cores aligned), RC pool base / raft / GF suspended slab (by others), vaulted cut roof with ridge beams, raked feature glazing
A14: Building height | B14: SCOTLAND: the design must satisfy the Building Standards (Scotland) technical handbooks (building warrant from South Lanarkshire Council) - not the English Approved Documents / LABC. Building height ~6.3 m above the ground floor (ridge) - below 11 m.
A15: Engineer / specialists | B15: ENGINEER / SPECIALISTS TO DESIGN (all slabs, roof timbers, steel posts, glazing and partitions are in the model for coordination only): the GF suspended slab over the pool and the 7.5 m garage (and the three ridge-post point loads that land on it), the 4.55 m garage door lintel, the vaulted roof ridge beams (120 x 400 GL24h glulam on steel posts; 140 x 800 GL24h glulam), the glazed gables; BS 8102 basement waterproofing (specialist designer); the ICF pool tank (pool specialist). NOT FOR CONSTRUCTION.
A16: Prepared by | B16: BuildEase (Tremco CPG UK) - BuildEase Design Suite quotation model
A17: Status | B17: FOR INFORMATION, COORDINATION AND PRICING BY OTHERS - rates blank; NOT part of the Nudura ICF price; NOT FOR CONSTRUCTION
A19: PACKAGE OVERVIEW - pricing by others (all amounts formula-linked to each bill's Package Summary)
A20: Bill | B20: Package | C20: Code / NRM2 | D20: Supply £ | E20: Install £ | F20: Total £
A21: Bill 1 | B21: External Wall Finish to the ICF (render / cladding - spec TBC) | C21: EXT NRM2 15 / 21 | D21: ='Bill 1 External Finish'!K27 | E21: ='Bill 1 External Finish'!L27 | F21: ='Bill 1 External Finish'!M27
A22: Bill 2 | B22: Internal Linings - Walls, Vaulted Ceilings, Tape, Beads & Skim | C22: DRY NRM2 28 | D22: ='Bill 2 Internal Linings'!K40 | E22: ='Bill 2 Internal Linings'!L40 | F22: ='Bill 2 Internal Linings'!M40
A23: Bill 3 | B23: Internal Doors & Ironmongery | C23: JOI NRM2 24 | D23: ='Bill 3 Doors'!K29 | E23: ='Bill 3 Doors'!L29 | F23: ='Bill 3 Doors'!M29
A24: Bill 4 | B24: Joinery - Skirtings, Architraves, Window Boards & Stair | C24: JOI NRM2 22 | D24: ='Bill 4 Joinery'!K31 | E24: ='Bill 4 Joinery'!L31 | F24: ='Bill 4 Joinery'!M31
A25: Bill 5 | B25: Timber Stud Partitions (TLSTF) - Framing, Openings, Head Restraint & Fixings | C25: JOI NRM2 16 | D25: ='Bill 5 Partitions'!K43 | E25: ='Bill 5 Partitions'!L43 | F25: ='Bill 5 Partitions'!M43
A26: Bill 6 | B26: Substructure & Slabs - Pool Base, Raft, GF Slab, Floor Build-ups (coordination) | C26: RCF / FLR NRM2 11 | D26: ='Bill 6 Slabs'!K33 | E26: ='Bill 6 Slabs'!L33 | F26: ='Bill 6 Slabs'!M33
A27: Bill 7 | B27: Vaulted Roof - Structure, Covering, Rainwater & Insulation | C27: RFS / RFC NRM2 16 / 18 | D27: ='Bill 7 Roof'!K49 | E27: ='Bill 7 Roof'!L49 | F27: ='Bill 7 Roof'!M49
A28: Bill 8 | B28: Glazing, External Doors, Raked Feature Screens & Garage Door | C28: WIN / GLZ NRM2 25 | D28: ='Bill 8 Glazing'!K44 | E28: ='Bill 8 Glazing'!L44 | F28: ='Bill 8 Glazing'!M44
A29: Bill 9 | B29: Basement Waterproofing (BS 8102) & ICF Pool Tank - PROVISIONAL | C29: WPF / POOL NRM2 17 | D29: ='Bill 9 Waterproofing Pool'!K31 | E29: ='Bill 9 Waterproofing Pool'!L31 | F29: ='Bill 9 Waterproofing Pool'!M31
A30: GRAND TOTAL - finishes / ancillary trades, net (excl. VAT) | D30: =SUM(D21:D29) | E30: =SUM(E21:E29) | F30: =SUM(F21:F29)
A32: Optional additions (enter %; blank = 0) | C32: % | F32: Amount £
A33: Preliminaries | B33: on the finishes net grand total | F33: =(F30)*N(C33)
A34: Overheads & profit | B34: on net total + preliminaries | F34: =(F30+F33)*N(C34)
A35: Contingency | B35: on net total + preliminaries + OH&P | F35: =(F30+F33+F34)*N(C35)
A36: GRAND TOTAL finishes incl. preliminaries, OH&P and contingency (excl. VAT) | F36: =F30+F33+F34+F35
A38: ICF PACKAGE HOOK - BuildEase BOQ Builder (ICF kit, concrete, labour, preliminaries, programme)
A39: Nudura ICF package (BuildEase BOQ Builder sheets of this workbook: Summary NET TOTAL) | F39: ='Summary'!$E$11
A40: COMBINED TOTAL - finishes package (incl. additions) + ICF package, excl. VAT | F40: =F36+N(F39)
A41: Pale-yellow cells are the only inputs (rates on each bill sheet, percentages and the ICF hook here). Everything else is a locked formula (protection has no password). Schedules A to D are reference only and are not priced. Named cells: FINISHES_NET_TOTAL, FINISHES_GRAND_TOTAL, ICF_PACKAGE_TOTAL, COMBINED_TOTAL.
A43: IMPORTANT - This information is supplied in good faith for guidance and coordination only. It is not part of the Nudura ICF price and must be checked and verified by the appropriate professional (quantity surveyor, designer, engineer or supplier) before use. Only the Nudura ICF formwork and associated accessories are included in our price. Quantities are measured from the BuildEase quotation model of the Foote McBride planning drawings (C2523 PP 01 001-008, raster, no sections / dimensions / levels - heights scaled from the elevations); no allowance for waste is included unless stated. Quantity columns are the model levels P / BL / FB / L1; the Site total is their sum. Rates and amounts are by others.
A45: KEY QUANTITIES (site totals: one dwelling, levels P / BL / FB / L1, net; linked to the bills)
A46: External finish to the ICF (GF + exposed below FFL) | D46: ='Bill 1 External Finish'!H10+'Bill 1 External Finish'!H11 | E46: m2
A47: Wall linings (ICF faces, partitions, reveals) | D47: ='Bill 2 Internal Linings'!H10+'Bill 2 Internal Linings'!H11+'Bill 2 Internal Linings'!H12+'Bill 2 Internal Linings'!H13+'Bill 2 Internal Linings'!H14+'Bill 2 Internal Linings'!H15+'Bill 2 Internal Linings'!H16+'Bill 2 Internal Linings'!H17+'Bill 2 Internal Linings'!H18 | E47: m2
...

Sheet General Notes
B1: General Notes, Measurement Basis, Assumptions & Exclusions
B2: ES26-084 | Plot 1 Rivendell Park, Douglas | Mr K & Mrs Burrell
A4: DISCLAIMER: This information is supplied in good faith for guidance and coordination only. It is not part of the Nudura ICF price and must be checked and verified by the appropriate professional (quantity surveyor, designer, engineer or supplier) before use. Only the Nudura ICF formwork and associated accessories are included in our price. Quantities are measured from the BuildEase quotation model of the Foote McBride planning drawings (C2523 PP 01 001-008, raster, no sections / dimensions / levels - heights scaled from the elevations); no allowance for waste is included unless stated. Quantity columns are the model levels P / BL / FB / L1; the Site total is their sum. Rates and amounts are by others.
A6: 1 Purpose, status, Scotland and building height
A7: 1.1 | B7: SCOTLAND: the design must satisfy the Building Standards (Scotland) technical handbooks (building warrant from South Lanarkshire Council) - not the English Approved Documents / LABC. Building height ~6.3 m above the ground floor (ridge) - below 11 m.
A8: 1.2 | B8: ENGINEER / SPECIALISTS TO DESIGN (all slabs, roof timbers, steel posts, glazing and partitions are in the model for coordination only): the GF suspended slab over the pool and the 7.5 m garage (and the three ridge-post point loads that land on it), the 4.55 m garage door lintel, the vaulted roof ridge beams (120 x 400 GL24h glulam on steel posts; 140 x 800 GL24h glulam), the glazed gables; BS 8102 basement waterproofing (specialist designer); the ICF pool tank (pool specialist). NOT FOR CONSTRUCTION.
A9: 1.3 | B9: This package presents the finishes and ancillary-trade quantities measured by BuildEase alongside the Nudura ICF quotation for Plot 1 Rivendell Park, Douglas (ref ES26-084). It is set out as a Bill of Quantities so that the client, their quantity surveyor and trade contractors can price and coordinate the works.
A10: 1.4 | B10: Status: FOR INFORMATION, COORDINATION AND PRICING BY OTHERS - NOT FOR CONSTRUCTION. Supply and install rates are left blank deliberately - BuildEase / Tremco CPG are not pricing these trades. The Excel workbook is a live pricing document: enter rates and every amount, subtotal and total updates by formula.
A11: 1.5 | B11: The ICF kit, concrete core, pumping, ICF / floor / roof labour and the build programme are in the BuildEase BOQ Builder sheets of this workbook (Cover / Programme / Summary / A-F). The finishes cover carries a named hook (ICF_PACKAGE_TOTAL) linked to that NET TOTAL.
A12: 1.6 | B12: PROGRAMME (BOQ Builder sheet 'Programme', 1 ICF crew of 8 + 1 joinery crew of 3, Tom's rule floors / roofs 1 day per plot, pours at 60 m3 / pump-day): 21 working days = 5 weeks. Sequence: ICF P d0-0.46; pour d1-2; cure d2-4; basement raft 300 RC d4-5; ICF BL d5-6.98; pour d9-10; GF suspended RC slab 250 d10-11; ICF FB d11-11.15; pour d14-15; ICF L1 d15-16.68; pour d19-20; vaulted roof structure d20-21. ICF concrete 98.32 m3 (geometric, ordered forms) in 4 pump days. ALIGNMENT: the proposal Rev B prices 3 stillages x 6 weeks hire (GBP 1,440.00); on this programme the alignment is needed from the first ICF lift (pool tank, day 0) to the last pour (GF L1, day 20) = 4 weeks on hire - 2 weeks LESS than priced (GBP 480.00 of hire not needed on this programme). SENSITIVITY: Tom's 1-day floor rule is written for timber floors; the two slabs here are RC (basement raft, GF suspended slab over the pool and the garage) - with 10 working days per slab for falsework / rebar / pour / cure before loading (engineer to confirm) the programme is 8 weeks and the alignment is on hire 8 weeks (+2 vs the 6 priced) unless it is off-hired between lifts. The proposal has NOT been changed - confirm the hire period with the client / site team.
A13: 1.7 | B13: This information is supplied in good faith for guidance and coordination only. It is not part of the Nudura ICF price and must be checked and verified by the appropriate professional (quantity surveyor, designer, engineer or supplier) before use. Only the Nudura ICF formwork and associated accessories are included in our price.
A14: 1.8 | B14: Quantities are measured from the BuildEase quotation model of the Foote McBride planning drawings (C2523 PP 01 001-008, raster, no sections / dimensions / levels - heights scaled from the elevations); no allowance for waste is included unless stated. Quantity columns are the model levels P / BL / FB / L1; the Site total is their sum. Rates and amounts are by others.
A16: 2 Basis of measurement
A17: 2.1 | B17: Measured generally in accordance with the principles of NRM2 (RICS New Rules of Measurement): work measured net as fixed in position, grouped by work section, units m / m2 / m3 / t / nr / item. NRM2 is referenced for structure only; descriptions are BuildEase's own.
A18: 2.2 | B18: Quantities are NET. No allowance for waste, laps, cutting or breakage is included unless stated; an "Order guide" with a stated waste % is guidance only.
A19: 2.3 | B19: Quantity columns: one column PER MODEL LEVEL - P pool tank, BL basement, FB master-suite footing, L1 ground floor. One dwelling: the Site total is the sum of the levels (multiplier 1) and is a live formula.
A20: 2.4 | B20: Sources: Foote McBride C2523 PP 01 001-008 (planning proposals, raster, Council Approval - planning only: no sections, dimensions or levels; heights and ground lines scaled from the elevations at 1:100); the BuildEase quotation model 03_Models/KB_build.skp through its specs (04_Logs/specs KB_spec.json, KB_slabs.json, KB_partitions.json), build reports (04_Logs/build: fbw_fit, floors, struct, TLSTF walls / doors / verify / rake / pattress / head-restraint) and the Report Tool component export (04_Logs/takeoff/KB_components.json: the inner / outer EPS face areas of the 588 modelled forms, openings net). Measured offline by 05_Scripts/kb_boq.py (no live model).
A22: 3 Assumptions
A23: 3.1 | B23: Walls: basement + pool tank 10in Std (387.4 overall), GF + master-suite footing 6in XR35 (355.6), cores centre-aligned. Frames tight to the back of the outer EPS (101.8 GF / 66.8 basement): internal reveal 211 GF / 278 basement.
A24: 3.2 | B24: Levels: GF FFL 0; basement FFL -3,300 (8 courses from -3,658); pool floor ~-4,800, pool walls from -5,029; FB -914 to 0; GF 14 courses to 6,401 (plate 2,286, gables raked at 45 deg, ridges ~6.0 m). GF slab top -75 (soffit -325) + 75 screed.
A25: 3.3 | B25: External finish: generic "render or cladding, spec TBC" (the elevations read show no wall hatch). Exposed below-FFL faces from ground lines scaled off the elevation renders (+-150): garage apron ~3.26 below FFL, west 3.31 falling to 2.71, east ~1.23, wing front ~0.9-1.1, rear terrace at DPC.
A26: 3.4 | B26: GF ceilings are vaulted throughout (plasterboard on the rafters, measured on the 45 deg slope); the GF partitions are raked to the vault (TLSTF rake profiles). Basement ceilings are the GF slab soffit; the garage ceiling / partitions are fire-resisting (warrant); the pool hall is by the pool specialist.
A27: 3.5 | B27: Internal doors: 13 from the TLSTF door report; leaves the largest standard 1,981 leaf that fits the opening less 68. Wet rooms from the pattress reports. Partitions: TLSTF 38 x 89 C16 at 600 (400 wet) - BF 8 walls 31.4 m / GF 20 walls 43.0 m = 74.4 m, 13 door openings.
A28: 3.6 | B28: Roof: rafters counted at 600 c/c between the gable walls (Roof L 35 per slope over 20.4 m, Roof R 20 per slope over 12.0 m), lengths on the 45 deg slope from the ridge face to the eaves overhang / valley; 5 rooflights read off the east elevation; covering 367.1 m2 on the slope.
A29: 3.7 | B29: Raked glazing: sills G01 / G03a at FFL, G05 at -960 (entrance), G02R on the dining bi-fold head (2,075); areas from the fbw_fit head profiles.
A31: 4 Exclusions (not measured in this package)
A32: 4.1 | B32: Nudura ICF formwork and accessories (in the Nudura price). ICF wall concrete, pumping, ICF / floor / roof labour and preliminaries are in the BOQ Builder sheets.
A33: 4.2 | B33: Supply of windows, doors, screens and the garage door are listed for pricing by the window / glazing / door suppliers (Bill 8) - not by BuildEase. Chimney / flue, external works, drainage, retaining walls beyond the house, landscaping.
A34: 4.3 | B34: Floor finishes, decorations, kitchens, sanitaryware, M&E services (UFH pipework, pool plant, MVHR / dehumidification) and builder's work.
A35: 4.4 | B35: Fire-stopping and fire-rated service penetrations, sealants and mastics, except where expressly described.
A37: 5 Open items / to be confirmed
A38: 5.1 | B38: STRUCTURAL ENGINEER: GF suspended slab over the pool and the 7.5 m garage incl. the three ridge-post point loads that land on it over the pool tank (Bill 6C.1); the 4.55 m garage door lintel under the lounge front wall; the vaulted roof ridge beams (120 x 400 GL24h on SHS posts; 140 x 800 GL24h glulam, rear bearing on the glazed dining gable); the glazed gables; the ICF pool tank; tall raked GF partitions (studs to ~5.8 m).
A39: 5.2 | B39: BS 8102 WATERPROOFING SPECIALIST: basement (Grade 3, habitable + pool hall) - system choice, Types A / B / C, sump and pumps, land drain (Bill 9A, provisional).
A40: 5.3 | B40: POOL SPECIALIST: pool depth (1.5 m assumed - outline only on the drawings), tanking / finish, coping, plant, pool hall environment and its linings / ceiling (Bills 2A.3, 2B.3, 9B).
A41: 5.4 | B41: GARAGE DOOR SUPPLIER: 4,555 x 2,394 sectional door (Bill 8E.2, provisional - not fitted in the model).
A42: 5.5 | B42: GLAZING SPECIALIST: the raked feature screens to the vault / glazed gables G01, G02R, G03a, G05 (Bill 8D) - design, wind load, mullions, safety glass, support of the glazed dining gable under the glulam ridge.
A43: 5.6 | B43: ARCHITECT / WARRANT (Building Standards (Scotland)): guarding to the floor-length windows where the ground is > 600 mm below (Standard 4.4, 8E.1); safety glazing (4.8); internal door widths (4.2 - the 680 / 762 openings); garage / dwelling fire separation (Section 2: doors, partitions, ceiling); noise between rooms (5.2); energy / U-values (Section 6); external finish specification (Bill 1).
A44: 5.7 | B44: Basement level: modelled AS DRAWN at FFL -3,300 (~3.27 m below GF FFL at the garage) - Tom had chosen "3.0 m" from a misread; the laundry door threshold is drawn 620 above the basement FFL (internal step) - confirm.
A45: 5.8 | B45: Not modelled (items flagged, not measured): chimney / stove flue (lounge west wall), the 5 rooflights (east slope, Bill 7B.9 counted from the elevation), the basement pool hall / hall glazed screen, the basement stair, the basement garage nib (0.6 m).
A46: 5.9 | B46: fbw_fit.json "glass_m2" for the raked screens under-reports the glass by about half (pane polygon vertex averaging in kb_windows.rb) - this BOQ re-measures from the head profiles (Schedule B lists both).
...

Sheet Summary of Bills
C1: Summary of Bills - section breakdown
C2: ES26-084 | Plot 1 Rivendell Park, Douglas | Mr K & Mrs Burrell - amounts by others, excl. VAT
A4: DISCLAIMER: This information is supplied in good faith for guidance and coordination only. It is not part of the Nudura ICF price and must be checked and verified by the appropriate professional (quantity surveyor, designer, engineer or supplier) before use. Only the Nudura ICF formwork and associated accessories are included in our price. Quantities are measured from the BuildEase quotation model of the Foote McBride planning drawings (C2523 PP 01 001-008, raster, no sections / dimensions / levels - heights scaled from the elevations); no allowance for waste is included unless stated. Quantity columns are the model levels P / BL / FB / L1; the Site total is their sum. Rates and amounts are by others.
A6: Bill | B6: Section | C6: Description | D6: Supply £ | E6: Install £ | F6: Total £
A7: 1 | B7: 1A | C7: External wall finish to the ICF (NRM2 15 / 21 - package EXT; system by others, SPEC TBC) | D7: ='Bill 1 External Finish'!K25 | E7: ='Bill 1 External Finish'!L25 | F7: ='Bill 1 External Finish'!M25
A8: 1 | B8: 1B | C8: Coordination items (supply by others) | D8: ='Bill 1 External Finish'!K26 | E8: ='Bill 1 External Finish'!L26 | F8: ='Bill 1 External Finish'!M26
A9: Bill 1 - External Wall Finish to the ICF (render / cladding - spec TBC) (package EXT) | D9: ='Bill 1 External Finish'!K27 | E9: ='Bill 1 External Finish'!L27 | F9: ='Bill 1 External Finish'!M27
A10: 2 | B10: 2A | C10: Wall linings (NRM2 28 / package DRY) | D10: ='Bill 2 Internal Linings'!K37 | E10: ='Bill 2 Internal Linings'!L37 | F10: ='Bill 2 Internal Linings'!M37
A11: 2 | B11: 2B | C11: Ceilings (NRM2 28 / package DRY) | D11: ='Bill 2 Internal Linings'!K38 | E11: ='Bill 2 Internal Linings'!L38 | F11: ='Bill 2 Internal Linings'!M38
A12: 2 | B12: 2C | C12: Jointing, beads and skim (NRM2 28 / package DRY) | D12: ='Bill 2 Internal Linings'!K39 | E12: ='Bill 2 Internal Linings'!L39 | F12: ='Bill 2 Internal Linings'!M39
A13: Bill 2 - Internal Linings - Walls, Vaulted Ceilings, Tape, Beads & Skim (package DRY) | D13: ='Bill 2 Internal Linings'!K40 | E13: ='Bill 2 Internal Linings'!L40 | F13: ='Bill 2 Internal Linings'!M40
A14: 3 | B14: 3A | C14: Internal doorsets (NRM2 24 / package JOI) | D14: ='Bill 3 Doors'!K27 | E14: ='Bill 3 Doors'!L27 | F14: ='Bill 3 Doors'!M27
A15: 3 | B15: 3B | C15: Ironmongery (NRM2 24 / package JOI) | D15: ='Bill 3 Doors'!K28 | E15: ='Bill 3 Doors'!L28 | F15: ='Bill 3 Doors'!M28
A16: Bill 3 - Internal Doors & Ironmongery (package JOI) | D16: ='Bill 3 Doors'!K29 | E16: ='Bill 3 Doors'!L29 | F16: ='Bill 3 Doors'!M29
A17: 4 | B17: 4A | C17: Skirtings (NRM2 22 / package JOI) | D17: ='Bill 4 Joinery'!K27 | E17: ='Bill 4 Joinery'!L27 | F17: ='Bill 4 Joinery'!M27
A18: 4 | B18: 4B | C18: Architraves (NRM2 22 / package JOI) | D18: ='Bill 4 Joinery'!K28 | E18: ='Bill 4 Joinery'!L28 | F18: ='Bill 4 Joinery'!M28
A19: 4 | B19: 4C | C19: Window boards (NRM2 22 / package JOI) | D19: ='Bill 4 Joinery'!K29 | E19: ='Bill 4 Joinery'!L29 | F19: ='Bill 4 Joinery'!M29
A20: 4 | B20: 4D | C20: Stairs and sundry joinery (NRM2 22 / package JOI) | D20: ='Bill 4 Joinery'!K30 | E20: ='Bill 4 Joinery'!L30 | F20: ='Bill 4 Joinery'!M30
A21: Bill 4 - Joinery - Skirtings, Architraves, Window Boards & Stair (package JOI) | D21: ='Bill 4 Joinery'!K31 | E21: ='Bill 4 Joinery'!L31 | F21: ='Bill 4 Joinery'!M31
A22: 5 | B22: 5A | C22: Timber stud partitions, non-loadbearing - framing (NRM2 16 / package JOI) | D22: ='Bill 5 Partitions'!K39 | E22: ='Bill 5 Partitions'!L39 | F22: ='Bill 5 Partitions'!M39
A23: 5 | B23: 5B | C23: Partition timber - supply (NRM2 16 / package JOI) | D23: ='Bill 5 Partitions'!K40 | E23: ='Bill 5 Partitions'!L40 | F23: ='Bill 5 Partitions'!M40
A24: 5 | B24: 5C | C24: Forming door openings in partitions (NRM2 16 / package JOI) | D24: ='Bill 5 Partitions'!K41 | E24: ='Bill 5 Partitions'!L41 | F24: ='Bill 5 Partitions'!M41
A25: 5 | B25: 5D | C25: Head restraint, pattresses, acoustic and fixings (NRM2 16 / package JOI) | D25: ='Bill 5 Partitions'!K42 | E25: ='Bill 5 Partitions'!L42 | F25: ='Bill 5 Partitions'!M42
A26: Bill 5 - Timber Stud Partitions (TLSTF) - Framing, Openings, Head Restraint & Fixings (package JOI) | D26: ='Bill 5 Partitions'!K43 | E26: ='Bill 5 Partitions'!L43 | F26: ='Bill 5 Partitions'!M43
A27: 6 | B27: 6A | C27: RC base, raft and slabs (NRM2 11 - package RCF; by others - engineer; coordination quantities) | D27: ='Bill 6 Slabs'!K30 | E27: ='Bill 6 Slabs'!L30 | F27: ='Bill 6 Slabs'!M30
A28: 6 | B28: 6B | C28: Floor build-ups (NRM2 11 / 28 - package FLR; by others) | D28: ='Bill 6 Slabs'!K31 | E28: ='Bill 6 Slabs'!L31 | F28: ='Bill 6 Slabs'!M31
A29: 6 | B29: 6C | C29: Coordination | D29: ='Bill 6 Slabs'!K32 | E29: ='Bill 6 Slabs'!L32 | F29: ='Bill 6 Slabs'!M32
A30: Bill 6 - Substructure & Slabs - Pool Base, Raft, GF Slab, Floor Build-ups (coordination) (package RCF / FLR) | D30: ='Bill 6 Slabs'!K33 | E30: ='Bill 6 Slabs'!L33 | F30: ='Bill 6 Slabs'!M33
A31: 7 | B31: 7A | C31: Roof structure - vaulted cut roof (NRM2 16 - package RFS; roof designer / engineer) | D31: ='Bill 7 Roof'!K46 | E31: ='Bill 7 Roof'!L46 | F31: ='Bill 7 Roof'!M46
A32: 7 | B32: 7B | C32: Roof covering, eaves, verges and rainwater (NRM2 18 / 33 - package RFC) | D32: ='Bill 7 Roof'!K47 | E32: ='Bill 7 Roof'!L47 | F32: ='Bill 7 Roof'!M47
A33: 7 | B33: 7C | C33: Roof insulation, VCL and soffits (NRM2 18 / 28 - package RFC) | D33: ='Bill 7 Roof'!K48 | E33: ='Bill 7 Roof'!L48 | F33: ='Bill 7 Roof'!M48
A34: Bill 7 - Vaulted Roof - Structure, Covering, Rainwater & Insulation (package RFS / RFC) | D34: ='Bill 7 Roof'!K49 | E34: ='Bill 7 Roof'!L49 | F34: ='Bill 7 Roof'!M49
A35: 8 | B35: 8A | C35: Windows - UPVC casements (NRM2 25 - package WIN; window supplier) | D35: ='Bill 8 Glazing'!K39 | E35: ='Bill 8 Glazing'!L39 | F35: ='Bill 8 Glazing'!M39
A36: 8 | B36: 8B | C36: External doors (NRM2 25 - package WIN) | D36: ='Bill 8 Glazing'!K40 | E36: ='Bill 8 Glazing'!L40 | F36: ='Bill 8 Glazing'!M40
A37: 8 | B37: 8C | C37: Glazed screens - stair (NRM2 25 - package WIN) | D37: ='Bill 8 Glazing'!K41 | E37: ='Bill 8 Glazing'!L41 | F37: ='Bill 8 Glazing'!M41
A38: 8 | B38: 8D | C38: Raked feature glazing screens to the vaulted roof / glazed gables (NRM2 25 - package GLZ; GLAZING SPECIALIST) | D38: ='Bill 8 Glazing'!K42 | E38: ='Bill 8 Glazing'!L42 | F38: ='Bill 8 Glazing'!M42
A39: 8 | B39: 8E | C39: Guarding, garage door and items not modelled (PROVISIONAL) | D39: ='Bill 8 Glazing'!K43 | E39: ='Bill 8 Glazing'!L43 | F39: ='Bill 8 Glazing'!M43
A40: Bill 8 - Glazing, External Doors, Raked Feature Screens & Garage Door (package WIN / GLZ) | D40: ='Bill 8 Glazing'!K44 | E40: ='Bill 8 Glazing'!L44 | F40: ='Bill 8 Glazing'!M44
A41: 9 | B41: 9A | C41: BS 8102:2022 waterproofing - PROVISIONAL (NRM2 17 - package WPF; SPECIALIST WATERPROOFING DESIGNER) | D41: ='Bill 9 Waterproofing Pool'!K29 | E41: ='Bill 9 Waterproofing Pool'!L29 | F41: ='Bill 9 Waterproofing Pool'!M29
A42: 9 | B42: 9B | C42: ICF pool tank (NRM2 - package POOL; POOL SPECIALIST - PROVISIONAL) | D42: ='Bill 9 Waterproofing Pool'!K30 | E42: ='Bill 9 Waterproofing Pool'!L30 | F42: ='Bill 9 Waterproofing Pool'!M30
...

Sheet Bill 1 External Finish
C1: Bill 1 - External Wall Finish to the ICF (render / cladding - spec TBC)
C2: External finish to the ICF EPS faces of the GF walls and the exposed basement / footing faces, with beads, trims and coordination items (system by others, spec TBC). [NRM2 15 / 21 / package EXT]
A4: DISCLAIMER: This information is supplied in good faith for guidance and coordination only. It is not part of the Nudura ICF price and must be checked and verified by the appropriate professional (quantity surveyor, designer, engineer or supplier) before use. Only the Nudura ICF formwork and associated accessories are included in our price. Quantities are measured from the BuildEase quotation model of the Foote McBride planning drawings (C2523 PP 01 001-008, raster, no sections / dimensions / levels - heights scaled from the elevations); no allowance for waste is included unless stated. Quantity columns are the model levels P / BL / FB / L1; the Site total is their sum. Rates and amounts are by others.
A6: Ref | B6: Description | C6: Unit | D6: P pool tank | E6: BL basement | F6: FB master footing | G6: L1 ground floor | H6: Site total qty | I6: Supply rate £ | J6: Install rate £ | K6: Supply £ | L6: Install £ | M6: Line total £ | N6: Notes
B7: One building - quantity per level (Site total = sum of the levels) | D7: 1 | E7: 1 | F7: 1 | G7: 1 | H7: =SUM(D7:G7) | N7: Levels: P = pool tank: 3 courses 10in Std, -5,029 to -3,658 (on the pool base); BL = basement: 8 courses 10in Std, FFL -3,300 - garage, laundry, stores, pool hall; FB = master-suite footing: 2 courses 6in XR35, -914 to 0 (no basement under it); L1 = ground floor: 14 courses 6in XR35 incl. the raked gables, vaulted ceilings
A8: 1A External wall finish to the ICF (NRM2 15 / 21 - package EXT; system by others, SPEC TBC)
B9: The Foote McBride elevations show the walls plain (no hatch / material key on the renders read) and the roof hatched as slate / tile: the external wall finish is measured generically as "external finish to the ICF EPS face - render or cladding system, spec TBC (by others)". Areas are the modelled ICF outer EPS faces (Report Tool component export, openings and glazing gaps already net): GF from FFL to the eaves plate (2,286) and up the raked gables; below FFL the exposed basement / footing faces down to finished ground, scaled off the elevation renders (+-150 mm; the faces and depths are listed in Schedule A). Where the ground is at DPC (rear, terrace) a 150 mm band is included.
A10: 1A.1 | B10: External finish to the ICF EPS face, GF walls incl. the raked gables (FFL to the plate / gable rake), net of openings: render or cladding system, spec TBC (base coat + mesh + finish, or battens + cladding) - by others | C10: m2 | G10: 161.985 | H10: =SUMPRODUCT($D$7:$G$7,D10:G10) | K10: =N(H10)*N(I10) | L10: =N(H10)*N(J10) | M10: =K10+L10 | N10: Order guide +10% = 178.2; GF outer faces 165.9 less the hall stub 3.9 (interior)
A11: 1A.2 | B11: Ditto, exposed basement / master-suite footing faces below FFL to finished ground (garage front + apron, west, east, wing front; DPC band at the rear), net of the basement openings - PROVISIONAL | C11: m2 | E11: 72.759 | F11: 4.611 | H11: =SUMPRODUCT($D$7:$G$7,D11:G11) | K11: =N(H11)*N(I11) | L11: =N(H11)*N(J11) | M11: =K11+L11 | N11: Ground lines scaled off the elevations (Schedule A); BL gross 90.1 less openings 17.4. Re-measure on the finished levels
A12: 1A.3 | B12: Reveal returns at windows / doors in the ICF (head + jambs; frames tight to the back of the outer EPS): girth 102 GF / 67 basement | C12: m2 | E12: 1.477 | G12: 5.231 | H12: =SUMPRODUCT($D$7:$G$7,D12:G12) | K12: =N(H12)*N(I12) | L12: =N(H12)*N(J12) | M12: =K12+L12 | N12: Order guide +10% = 7.4; GF windows are floor-length (no sill reveal)
A13: 1A.4 | B13: Returns at the ICF wall ends beside the glazed screens and glazing gaps (jamb returns ~102 girth), incl. stop / edge bead | C13: m | E13: 11.172 | G13: 30.835 | H13: =SUMPRODUCT($D$7:$G$7,D13:G13) | K13: =N(H13)*N(I13) | L13: =N(H13)*N(J13) | M13: =K13+L13 | N13: Screens G01, G02 / G02R, G03a / b, G05, BL-G04 (Schedule B); G03a / G03b meet at a glazed corner
A14: 1A.5 | B14: External corner bead / angle to the vertical external corners (GF to the plate / gable; basement / footing corners to ground) | C14: m | E14: 6.664 | F14: 0.365 | G14: 16.916 | H14: =SUMPRODUCT($D$7:$G$7,D14:G14) | K14: =N(H14)*N(I14) | L14: =N(H14)*N(J14) | M14: =K14+L14 | N14: Order guide +10% = 26.3
A15: 1A.6 | B15: Base / starter track (bellcast bead, drip) at finished ground or DPC level, incl. below-ground termination of the finish | C15: m | E15: 45.786 | F15: 14.811 | H15: =SUMPRODUCT($D$7:$G$7,D15:G15) | K15: =N(H15)*N(I15) | L15: =N(H15)*N(J15) | M15: =K15+L15 | N15: Order guide +10% = 66.7; door thresholds deducted (garage door, laundry door)
A16: 1A.7 | B16: Head stop / closure bead at the eaves soffit (eaves walls) and along the gable verge rakes | C16: m | G16: 66.684 | H16: =SUMPRODUCT($D$7:$G$7,D16:G16) | K16: =N(H16)*N(I16) | L16: =N(H16)*N(J16) | M16: =K16+L16 | N16: Eaves walls 38.8 + gable rakes 27.9; Order guide +10% = 73.4
A17: 1A.8 | B17: Movement / sealant joint between the finish and the window, door and screen frames (backer rod + low-modulus sealant) | C17: m | E17: 33.283 | G17: 82.22 | H17: =SUMPRODUCT($D$7:$G$7,D17:G17) | K17: =N(H17)*N(I17) | L17: =N(H17)*N(J17) | M17: =K17+L17 | N17: Order guide +10% = 127.1
A18: 1B Coordination items (supply by others)
A19: 1B.1 | B19: External cills / thresholds at the structural openings (GF: floor-length windows + bi-folds = thresholds; basement: pool windows + laundry door) | C19: m | E19: 9.675 | G19: 14.035 | H19: =SUMPRODUCT($D$7:$G$7,D19:G19) | K19: =N(H19)*N(I19) | L19: =N(H19)*N(J19) | M19: =K19+L19 | N19: By the window / door supplier - coordination only
A20: 1B.2 | B20: Chimney / stove flue on the lounge west wall (drawn on the elevations, NOT modelled): finish, flashings and flue by others | C20: item | K20: =IF(ISNUMBER(H20),H20,1)*N(I20) | L20: =IF(ISNUMBER(H20),H20,1)*N(J20) | M20: =K20+L20 | N20: Lump sum - the rate entered is the amount. Not measured - chimney not in the model
A21: 1B.3 | B21: Basement rear retaining wall running on 1.5 m past the house (x 15,076-16,744): exposed face finish / backfill by the groundworker | C21: item | K21: =IF(ISNUMBER(H21),H21,1)*N(I21) | L21: =IF(ISNUMBER(H21),H21,1)*N(J21) | M21: =K21+L21 | N21: Lump sum - the rate entered is the amount. Exposure not shown on the elevations - not measured
A23: PACKAGE SUMMARY - Bill 1 External Wall Finish to the ICF (render / cladding - spec TBC) (package EXT; amounts by others, excl. VAT)
A24: Section | B24: Description | K24: Supply £ | L24: Install £ | M24: Total £
A25: 1A | B25: External wall finish to the ICF (NRM2 15 / 21 - package EXT; system by others, SPEC TBC) | K25: =SUM(K9:K17) | L25: =SUM(L9:L17) | M25: =SUM(M9:M17)
A26: 1B | B26: Coordination items (supply by others) | K26: =SUM(K19:K21) | L26: =SUM(L19:L21) | M26: =SUM(M19:M21)
A27: PACKAGE TOTAL - Bill 1, carried to the Cover overview | K27: =SUM(K25:K26) | L27: =SUM(L25:L26) | M27: =SUM(M25:M26)
A28: Pale-yellow cells are the only inputs (Supply rate, Install rate). Amounts, subtotals and totals are formulas; the sheet is protected without a password (Review > Unprotect Sheet). Amounts exclude VAT and are NOT part of the Nudura ICF price.

Sheet Bill 2 Internal Linings
C1: Bill 2 - Internal Linings - Walls, Vaulted Ceilings, Tape, Beads & Skim
C2: Dry linings to the ICF inner faces (thermal barrier to the EPS), TLSTF partitions, reveals, basement ceilings and the GF vaulted ceilings (on the slope). [NRM2 28 / package DRY]
A4: DISCLAIMER: This information is supplied in good faith for guidance and coordination only. It is not part of the Nudura ICF price and must be checked and verified by the appropriate professional (quantity surveyor, designer, engineer or supplier) before use. Only the Nudura ICF formwork and associated accessories are included in our price. Quantities are measured from the BuildEase quotation model of the Foote McBride planning drawings (C2523 PP 01 001-008, raster, no sections / dimensions / levels - heights scaled from the elevations); no allowance for waste is included unless stated. Quantity columns are the model levels P / BL / FB / L1; the Site total is their sum. Rates and amounts are by others.
A6: Ref | B6: Description | C6: Unit | D6: P pool tank | E6: BL basement | F6: FB master footing | G6: L1 ground floor | H6: Site total qty | I6: Supply rate £ | J6: Install rate £ | K6: Supply £ | L6: Install £ | M6: Line total £ | N6: Notes
B7: One building - quantity per level (Site total = sum of the levels) | D7: 1 | E7: 1 | F7: 1 | G7: 1 | H7: =SUM(D7:G7) | N7: Levels: P = pool tank: 3 courses 10in Std, -5,029 to -3,658 (on the pool base); BL = basement: 8 courses 10in Std, FFL -3,300 - garage, laundry, stores, pool hall; FB = master-suite footing: 2 courses 6in XR35, -914 to 0 (no basement under it); L1 = ground floor: 14 courses 6in XR35 incl. the raked gables, vaulted ceilings
A8: 2A Wall linings (NRM2 28 / package DRY)
B9: Measured on the modelled ICF inner EPS faces (component export, openings net). Basement: FFL -3,300 to the GF slab soffit -325 (2,975 clear); GF: FFL to the vaulted ceiling - the gable triangles and the eaves walls up to the rafters are lined (vaulted rooms). TLSTF partitions both faces, door gaps deducted (2,100 high); GF partitions are raked to the vault (200.9 m2 one face). EPS faces must be covered by a thermal barrier (min. 12.5 mm board, mechanically fixed to the ICF webs) whatever the finish. Basement linings follow the BS 8102 design (Bill 9): with a Type C cavity drain the board goes on battens inside the membrane - PROVISIONAL build-up.
A10: 2A.1 | B10: Basement ICF inner face - stair / hall, stores, laundry, plant (FFL -3,300 to -325): 12.5 mm board on battens / inside the cavity drain membrane (BS 8102 - PROVISIONAL) | C10: m2 | E10: 84.738 | H10: =SUMPRODUCT($D$7:$G$7,D10:G10) | K10: =N(H10)*N(I10) | L10: =N(H10)*N(J10) | M10: =K10+L10 | N10: incl. both faces of the internal ICF store nib + stub (8.8); Order guide +10% = 93.2
A11: 2A.2 | B11: Garage ICF inner face (integral garage): 12.5 mm board mechanically fixed (EPS thermal barrier); fire-resisting lining where the warrant requires | C11: m2 | E11: 32.593 | H11: =SUMPRODUCT($D$7:$G$7,D11:G11) | K11: =N(H11)*N(I11) | L11: =N(H11)*N(J11) | M11: =K11+L11 | N11: Order guide +10% = 35.9
A12: 2A.3 | B12: Pool hall walls (ICF inner face around the pool): moisture-resistant / cement-based board + tanking + tiling by the pool specialist - PROVISIONAL | C12: m2 | E12: 41.364 | H12: =SUMPRODUCT($D$7:$G$7,D12:G12) | K12: =N(H12)*N(I12) | L12: =N(H12)*N(J12) | M12: =K12+L12 | N12: Pool specialist; Order guide +10% = 45.5
A13: 2A.4 | B13: GF ICF inner face incl. the gable triangles up to the vault + the hall face of the wing stub: 12.5 mm wallboard on dabs + mechanical fixings to the ICF webs (MR board in the ensuites / cloaks) | C13: m2 | G13: 161.85 | H13: =SUMPRODUCT($D$7:$G$7,D13:G13) | K13: =N(H13)*N(I13) | L13: =N(H13)*N(J13) | M13: =K13+L13 | N13: inner faces 157.9 + stub 3.9; Order guide +10% = 178.0
A14: 2A.5 | B14: Basement TLSTF partitions - both faces (garage faces in 2A.6): 15 mm board on 38 x 89 studs; MR in the laundry | C14: m2 | E14: 128.972 | H14: =SUMPRODUCT($D$7:$G$7,D14:G14) | K14: =N(H14)*N(I14) | L14: =N(H14)*N(J14) | M14: =K14+L14 | N14: Order guide +10% = 141.9
A15: 2A.6 | B15: Garage faces of the garage / dwelling partitions BF-P03 + BF-P04: fire-resisting board (e.g. 2 x 15 mm FR) per the building warrant (Section 2 Fire) - PROVISIONAL | C15: m2 | E15: 36.525 | H15: =SUMPRODUCT($D$7:$G$7,D15:G15) | K15: =N(H15)*N(I15) | L15: =N(H15)*N(J15) | M15: =K15+L15 | N15: Separation garage / dwelling; Order guide +10% = 40.2
A16: 2A.7 | B16: GF TLSTF partitions - both faces, raked heads to the vaulted ceiling: 15 mm board on 38 x 89 studs; MR in the ensuites / cloaks | C16: m2 | G16: 379.369 | H16: =SUMPRODUCT($D$7:$G$7,D16:G16) | K16: =N(H16)*N(I16) | L16: =N(H16)*N(J16) | M16: =K16+L16 | N16: Tall raked walls - board to 5.9 m; Order guide +10% = 417.3
A17: 2A.8 | B17: Internal reveals to windows / doors in the ICF, jambs and heads, 211 deep GF / 278 basement: board / bonding + skim | C17: m2 | E17: 6.148 | G17: 10.858 | H17: =SUMPRODUCT($D$7:$G$7,D17:G17) | K17: =N(H17)*N(I17) | L17: =N(H17)*N(J17) | M17: =K17+L17 | N17: Order guide +10% = 18.7
A18: 2A.9 | B18: Internal returns at the ICF wall ends beside the glazed screens (same depth as the reveals) | C18: m2 | E18: 3.106 | G18: 6.515 | H18: =SUMPRODUCT($D$7:$G$7,D18:G18) | K18: =N(H18)*N(I18) | L18: =N(H18)*N(J18) | M18: =K18+L18 | N18: Order guide +10% = 10.6
A19: 2B Ceilings (NRM2 28 / package DRY)
B20: Basement: the soffit of the GF suspended slab (-325), net plan areas (Schedule A). GF: VAULTED throughout - plasterboard on the rafter soffits, MEASURED ON THE SLOPE (45 deg: plan 199.8 m2 x 1.414); the insulation / VCL build-up is in Bill 7C.
A21: 2B.1 | B21: Basement ceilings (stair / hall, stores, laundry) under the GF slab: MF ceiling grid + 12.5 mm board, or tape-and-fill direct to the slab | C21: m2 | E21: 87.539 | H21: =SUMPRODUCT($D$7:$G$7,D21:G21) | K21: =N(H21)*N(I21) | L21: =N(H21)*N(J21) | M21: =K21+L21 | N21: Order guide +10% = 96.3
A22: 2B.2 | B22: Integral garage ceiling under the dwelling: fire-resisting ceiling (e.g. 2 x 15 mm FR board on MF) per the warrant - PROVISIONAL | C22: m2 | E22: 49.049 | H22: =SUMPRODUCT($D$7:$G$7,D22:G22) | K22: =N(H22)*N(I22) | L22: =N(H22)*N(J22) | M22: =K22+L22 | N22: Garage 7.0 x 7.0
A23: 2B.3 | B23: Pool hall ceiling: moisture-resistant board + VCL (pool hall environment) - by / to the pool specialist, PROVISIONAL | C23: m2 | E23: 43.401 | H23: =SUMPRODUCT($D$7:$G$7,D23:G23) | K23: =N(H23)*N(I23) | L23: =N(H23)*N(J23) | M23: =K23+L23 | N23: Pool specialist
A24: 2B.4 | B24: GF vaulted ceilings: 12.5 mm board (or insulated board) on the rafter soffits, measured on the 45 deg slope | C24: m2 | G24: 282.549 | H24: =SUMPRODUCT($D$7:$G$7,D24:G24) | K24: =N(H24)*N(I24) | L24: =N(H24)*N(J24) | M24: =K24+L24 | N24: Order guide +10% = 310.8; plan 199.8 m2
A25: 2B.5 | B25: Ridge beam linings / boxings where the beams drop below the vault: Roof L 120 x 400 GL24h (20.7 m), Roof R 140 x 800 GL24h (12.3 m) - or exposed feature finish (client) | C25: m | G25: 32.745 | H25: =SUMPRODUCT($D$7:$G$7,D25:G25) | K25: =N(H25)*N(I25) | L25: =N(H25)*N(J25) | M25: =K25+L25 | N25: Girth to suit; glulam may be left exposed
A26: 2C Jointing, beads and skim (NRM2 28 / package DRY)
A27: 2C.1 | B27: Scrim tape, board joints (walls / 1.2 m; ceilings / 1.2 + 2.4 m) | C27: m | E27: 414.137 | G27: 818.681 | H27: =SUMPRODUCT($D$7:$G$7,D27:G27) | K27: =N(H27)*N(I27) | L27: =N(H27)*N(J27) | M27: =K27+L27 | N27: Order guide +10% = 1,356.1
A28: 2C.2 | B28: Scrim tape, internal angles wall to wall (4 per partition + ICF internal corners) | C28: m | E28: 113.05 | G28: 401.905 | H28: =SUMPRODUCT($D$7:$G$7,D28:G28) | K28: =N(H28)*N(I28) | L28: =N(H28)*N(J28) | M28: =K28+L28 | N28: Estimate - no room model; Order guide +10% = 566.5
A29: 2C.3 | B29: Scrim tape, wall to ceiling angles (eaves / gable heads + partition heads both sides) | C29: m | E29: 106.155 | G29: 171.441 | H29: =SUMPRODUCT($D$7:$G$7,D29:G29) | K29: =N(H29)*N(I29) | L29: =N(H29)*N(J29) | M29: =K29+L29 | N29: Estimate; Order guide +10% = 305.4
A30: 2C.4 | B30: Angle bead, window / door reveals and screen-end returns | C30: m | E30: 33.283 | G30: 82.22 | H30: =SUMPRODUCT($D$7:$G$7,D30:G30) | K30: =N(H30)*N(I30) | L30: =N(H30)*N(J30) | M30: =K30+L30 | N30: Order guide +10% = 127.1
A31: 2C.5 | B31: Skim coat, 2-3 mm, to all net wall, reveal and ceiling board faces (pool hall excluded - specialist) | C31: m2 | E31: 428.67 | G31: 841.142 | H31: =SUMPRODUCT($D$7:$G$7,D31:G31) | K31: =N(H31)*N(I31) | L31: =N(H31)*N(J31) | M31: =K31+L31 | N31: Face layer only
A32: 2D Ordering guide (not a measured item)
A33: 2D.1 | B33: Plasterboard to purchase, all types, before waste (excl. pool hall) | C33: m2 | E33: 428.67 | G33: 841.142 | H33: =SUMPRODUCT($D$7:$G$7,D33:G33) | M33: not priced | N33: Order guide +10% = 1,396.8 (guide only)
A35: PACKAGE SUMMARY - Bill 2 Internal Linings - Walls, Vaulted Ceilings, Tape, Beads & Skim (package DRY; amounts by others, excl. VAT)
A36: Section | B36: Description | K36: Supply £ | L36: Install £ | M36: Total £
A37: 2A | B37: Wall linings (NRM2 28 / package DRY) | K37: =SUM(K9:K18) | L37: =SUM(L9:L18) | M37: =SUM(M9:M18)
A38: 2B | B38: Ceilings (NRM2 28 / package DRY) | K38: =SUM(K20:K25) | L38: =SUM(L20:L25) | M38: =SUM(M20:M25)
